{"activity":"ghpages","category":"activity-error","message":"activity failed with execption:\nTraceback (most recent call last):\n  File \"/home/scopatz/.local/lib/python3.6/site-packages/rever-0.1.0-py3.6.egg/rever/activity.xsh\", line 59, in __call__\n    self.func(*args, **kwargs)\n  File \"/home/scopatz/.local/lib/python3.6/site-packages/rever-0.1.0-py3.6.egg/rever/activities/ghpages.xsh\", line 64, in _func\n    copy = expand_copy(copy)\n  File \"/home/scopatz/.local/lib/python3.6/site-packages/rever-0.1.0-py3.6.egg/rever/activities/ghpages.xsh\", line 42, in expand_copy\n    if not os.path.exist(src):\nAttributeError: module 'posixpath' has no attribute 'exist'\nrewinding to 49da7a34be1aa08f5d7a9565b86d1645b07c9d14","rev":"6ee2e7b8b878c0861c66eb193ec40e559c52b798","timestamp":1510788487.8806913}
{"activity":"ghpages","category":"activity-error","message":"activity failed with execption:\nTraceback (most recent call last):\n  File \"/home/scopatz/.local/lib/python3.6/site-packages/rever-0.1.0-py3.6.egg/rever/activity.xsh\", line 59, in __call__\n    self.func(*args, **kwargs)\n  File \"/home/scopatz/.local/lib/python3.6/site-packages/rever-0.1.0-py3.6.egg/rever/activities/ghpages.xsh\", line 75, in _func\n    git commit -am @(msg)\n  File \"/home/scopatz/.local/lib/python3.6/site-packages/xonsh/__amalgam__.py\", line 19376, in subproc_captured_hiddenobject\n    return run_subproc(cmds, captured='hiddenobject')\n  File \"/home/scopatz/.local/lib/python3.6/site-packages/xonsh/__amalgam__.py\", line 19339, in run_subproc\n    command.end()\n  File \"/home/scopatz/.local/lib/python3.6/site-packages/xonsh/__amalgam__.py\", line 12645, in end\n    self._end(tee_output=tee_output)\n  File \"/home/scopatz/.local/lib/python3.6/site-packages/xonsh/__amalgam__.py\", line 12664, in _end\n    self._raise_subproc_error()\n  File \"/home/scopatz/.local/lib/python3.6/site-packages/xonsh/__amalgam__.py\", line 12774, in _raise_subproc_error\n    output=self.output)\nsubprocess.CalledProcessError: Command '['/home/scopatz/miniconda/bin/git', 'commit', '-am', 'GitHub pages update for 0.2.0']' returned non-zero exit status 1.\nrewinding to 49da7a34be1aa08f5d7a9565b86d1645b07c9d14","rev":"8596a742e504e7c208a53b32cfd1e012256a5114","timestamp":1510789171.5915885}
{"activity":"ghpages","category":"activity-error","message":"activity failed with execption:\nTraceback (most recent call last):\n  File \"/home/scopatz/.local/lib/python3.6/site-packages/rever-0.1.0-py3.6.egg/rever/activity.xsh\", line 59, in __call__\n    self.func(*args, **kwargs)\n  File \"/home/scopatz/.local/lib/python3.6/site-packages/rever-0.1.0-py3.6.egg/rever/activities/ghpages.xsh\", line 65, in _func\n    copy = expand_copy(copy)\n  File \"/home/scopatz/.local/lib/python3.6/site-packages/rever-0.1.0-py3.6.egg/rever/activities/ghpages.xsh\", line 42, in expand_copy\n    print('!!! ' + srco)\nNameError: name 'srco' is not defined\nrewinding to 49da7a34be1aa08f5d7a9565b86d1645b07c9d14","rev":"394a134cefa01a88bf23421e18e80b44ddf6b29c","timestamp":1510789546.46406}
{"activity":"ghpages","category":"activity-error","message":"activity failed with execption:\nTraceback (most recent call last):\n  File \"/home/scopatz/.local/lib/python3.6/site-packages/rever-0.1.0-py3.6.egg/rever/activity.xsh\", line 59, in __call__\n    self.func(*args, **kwargs)\n  File \"/home/scopatz/.local/lib/python3.6/site-packages/rever-0.1.0-py3.6.egg/rever/activities/ghpages.xsh\", line 68, in _func\n    print_color(msg)\nNameError: name 'print_color' is not defined\nrewinding to 49da7a34be1aa08f5d7a9565b86d1645b07c9d14","rev":"2eada42aa305ce2cdd5738a0a052e229246a3ea6","timestamp":1510789678.2451131}
{"activity":"ghpages","category":"activity-error","message":"activity failed with execption:\nTraceback (most recent call last):\n  File \"/home/scopatz/.local/lib/python3.5/site-packages/rever-0.1.0-py3.5.egg/rever/activity.xsh\", line 59, in __call__\n    self.func(*args, **kwargs)\n  File \"/home/scopatz/.local/lib/python3.5/site-packages/rever-0.1.0-py3.5.egg/rever/activities/ghpages.xsh\", line 78, in _func\n    if p.rtn == 0 and q.rtn == 0:\n  File \"/home/scopatz/.local/lib/python3.5/site-packages/xonsh/__amalgam__.py\", line 12839, in rtn\n    return self.returncode\n  File \"/home/scopatz/.local/lib/python3.5/site-packages/xonsh/__amalgam__.py\", line 12826, in returncode\n    self.end()\n  File \"/home/scopatz/.local/lib/python3.5/site-packages/xonsh/__amalgam__.py\", line 12645, in end\n    self._end(tee_output=tee_output)\n  File \"/home/scopatz/.local/lib/python3.5/site-packages/xonsh/__amalgam__.py\", line 12653, in _end\n    for _ in self.tee_stdout():\n  File \"/home/scopatz/.local/lib/python3.5/site-packages/xonsh/__amalgam__.py\", line 12569, in tee_stdout\n    for line in self.iterraw():\n  File \"/home/scopatz/.local/lib/python3.5/site-packages/xonsh/__amalgam__.py\", line 12462, in iterraw\n    self.end(tee_output=False)\n  File \"/home/scopatz/.local/lib/python3.5/site-packages/xonsh/__amalgam__.py\", line 12645, in end\n    self._end(tee_output=tee_output)\n  File \"/home/scopatz/.local/lib/python3.5/site-packages/xonsh/__amalgam__.py\", line 12664, in _end\n    self._raise_subproc_error()\n  File \"/home/scopatz/.local/lib/python3.5/site-packages/xonsh/__amalgam__.py\", line 12774, in _raise_subproc_error\n    output=self.output)\nsubprocess.CalledProcessError: Command '['/usr/bin/git', 'diff', '--exit-code', '--quiet']' returned non-zero exit status 1\nrewinding to a077dbc7a4fec63328bb79b74bf19009923528e7","rev":"ded7c7adfdf7f07ad58d8b04626b9d745aaac092","timestamp":1510795079.1390636}
{"activity":"ghpages","category":"activity-error","message":"activity failed with execption:\nTraceback (most recent call last):\n  File \"/home/scopatz/.local/lib/python3.5/site-packages/rever-0.1.0-py3.5.egg/rever/activity.xsh\", line 59, in __call__\n    self.func(*args, **kwargs)\n  File \"/home/scopatz/.local/lib/python3.5/site-packages/rever-0.1.0-py3.5.egg/rever/activities/ghpages.xsh\", line 78, in _func\n    if p.rtn == 0 and q.rtn == 0:\n  File \"/home/scopatz/.local/lib/python3.5/site-packages/xonsh/__amalgam__.py\", line 12839, in rtn\n    return self.returncode\n  File \"/home/scopatz/.local/lib/python3.5/site-packages/xonsh/__amalgam__.py\", line 12826, in returncode\n    self.end()\n  File \"/home/scopatz/.local/lib/python3.5/site-packages/xonsh/__amalgam__.py\", line 12645, in end\n    self._end(tee_output=tee_output)\n  File \"/home/scopatz/.local/lib/python3.5/site-packages/xonsh/__amalgam__.py\", line 12653, in _end\n    for _ in self.tee_stdout():\n  File \"/home/scopatz/.local/lib/python3.5/site-packages/xonsh/__amalgam__.py\", line 12569, in tee_stdout\n    for line in self.iterraw():\n  File \"/home/scopatz/.local/lib/python3.5/site-packages/xonsh/__amalgam__.py\", line 12462, in iterraw\n    self.end(tee_output=False)\n  File \"/home/scopatz/.local/lib/python3.5/site-packages/xonsh/__amalgam__.py\", line 12645, in end\n    self._end(tee_output=tee_output)\n  File \"/home/scopatz/.local/lib/python3.5/site-packages/xonsh/__amalgam__.py\", line 12664, in _end\n    self._raise_subproc_error()\n  File \"/home/scopatz/.local/lib/python3.5/site-packages/xonsh/__amalgam__.py\", line 12774, in _raise_subproc_error\n    output=self.output)\nsubprocess.CalledProcessError: Command '['/usr/bin/git', 'diff', '--exit-code', '--quiet']' returned non-zero exit status 1\nrewinding to a077dbc7a4fec63328bb79b74bf19009923528e7","rev":"ded7c7adfdf7f07ad58d8b04626b9d745aaac092","timestamp":1510795097.6513655}
{"activity":"ghpages","category":"activity-error","message":"activity failed with execption:\nTraceback (most recent call last):\n  File \"/home/scopatz/.local/lib/python3.5/site-packages/rever-0.1.0-py3.5.egg/rever/activity.xsh\", line 59, in __call__\n    self.func(*args, **kwargs)\n  File \"/home/scopatz/.local/lib/python3.5/site-packages/rever-0.1.0-py3.5.egg/rever/activities/ghpages.xsh\", line 78, in _func\n    if p.rtn == 0 and q.rtn == 0:\n  File \"/home/scopatz/.local/lib/python3.5/site-packages/xonsh/__amalgam__.py\", line 12839, in rtn\n    return self.returncode\n  File \"/home/scopatz/.local/lib/python3.5/site-packages/xonsh/__amalgam__.py\", line 12826, in returncode\n    self.end()\n  File \"/home/scopatz/.local/lib/python3.5/site-packages/xonsh/__amalgam__.py\", line 12645, in end\n    self._end(tee_output=tee_output)\n  File \"/home/scopatz/.local/lib/python3.5/site-packages/xonsh/__amalgam__.py\", line 12653, in _end\n    for _ in self.tee_stdout():\n  File \"/home/scopatz/.local/lib/python3.5/site-packages/xonsh/__amalgam__.py\", line 12569, in tee_stdout\n    for line in self.iterraw():\n  File \"/home/scopatz/.local/lib/python3.5/site-packages/xonsh/__amalgam__.py\", line 12462, in iterraw\n    self.end(tee_output=False)\n  File \"/home/scopatz/.local/lib/python3.5/site-packages/xonsh/__amalgam__.py\", line 12645, in end\n    self._end(tee_output=tee_output)\n  File \"/home/scopatz/.local/lib/python3.5/site-packages/xonsh/__amalgam__.py\", line 12664, in _end\n    self._raise_subproc_error()\n  File \"/home/scopatz/.local/lib/python3.5/site-packages/xonsh/__amalgam__.py\", line 12774, in _raise_subproc_error\n    output=self.output)\nsubprocess.CalledProcessError: Command '['/usr/bin/git', 'diff', '--exit-code', '--quiet']' returned non-zero exit status 1\nrewinding to a077dbc7a4fec63328bb79b74bf19009923528e7","rev":"ded7c7adfdf7f07ad58d8b04626b9d745aaac092","timestamp":1510795208.373894}
{"activity":"ghpages","category":"activity-error","message":"activity failed with execption:\nTraceback (most recent call last):\n  File \"/home/scopatz/.local/lib/python3.5/site-packages/rever-0.1.0-py3.5.egg/rever/activity.xsh\", line 59, in __call__\n    self.func(*args, **kwargs)\n  File \"/home/scopatz/.local/lib/python3.5/site-packages/rever-0.1.0-py3.5.egg/rever/activities/ghpages.xsh\", line 74, in _func\n    print(RAISE_SUBPROC_ERRORo)\nNameError: name 'RAISE_SUBPROC_ERRORo' is not defined\nrewinding to a077dbc7a4fec63328bb79b74bf19009923528e7","rev":"ded7c7adfdf7f07ad58d8b04626b9d745aaac092","timestamp":1510795265.4967186}
{"activity":"ghpages","category":"activity-error","message":"activity failed with execption:\nTraceback (most recent call last):\n  File \"/home/scopatz/.local/lib/python3.5/site-packages/rever-0.1.0-py3.5.egg/rever/activity.xsh\", line 59, in __call__\n    self.func(*args, **kwargs)\n  File \"/home/scopatz/.local/lib/python3.5/site-packages/rever-0.1.0-py3.5.egg/rever/activities/ghpages.xsh\", line 79, in _func\n    if p.rtn == 0 and q.rtn == 0:\n  File \"/home/scopatz/.local/lib/python3.5/site-packages/xonsh/__amalgam__.py\", line 12839, in rtn\n    return self.returncode\n  File \"/home/scopatz/.local/lib/python3.5/site-packages/xonsh/__amalgam__.py\", line 12826, in returncode\n    self.end()\n  File \"/home/scopatz/.local/lib/python3.5/site-packages/xonsh/__amalgam__.py\", line 12645, in end\n    self._end(tee_output=tee_output)\n  File \"/home/scopatz/.local/lib/python3.5/site-packages/xonsh/__amalgam__.py\", line 12653, in _end\n    for _ in self.tee_stdout():\n  File \"/home/scopatz/.local/lib/python3.5/site-packages/xonsh/__amalgam__.py\", line 12569, in tee_stdout\n    for line in self.iterraw():\n  File \"/home/scopatz/.local/lib/python3.5/site-packages/xonsh/__amalgam__.py\", line 12462, in iterraw\n    self.end(tee_output=False)\n  File \"/home/scopatz/.local/lib/python3.5/site-packages/xonsh/__amalgam__.py\", line 12645, in end\n    self._end(tee_output=tee_output)\n  File \"/home/scopatz/.local/lib/python3.5/site-packages/xonsh/__amalgam__.py\", line 12664, in _end\n    self._raise_subproc_error()\n  File \"/home/scopatz/.local/lib/python3.5/site-packages/xonsh/__amalgam__.py\", line 12774, in _raise_subproc_error\n    output=self.output)\nsubprocess.CalledProcessError: Command '['/usr/bin/git', 'diff', '--exit-code', '--quiet']' returned non-zero exit status 1\nrewinding to a077dbc7a4fec63328bb79b74bf19009923528e7","rev":"ded7c7adfdf7f07ad58d8b04626b9d745aaac092","timestamp":1510795280.288953}
{"activity":"ghpages","category":"activity-error","message":"activity failed with execption:\nTraceback (most recent call last):\n  File \"/home/scopatz/.local/lib/python3.5/site-packages/rever-0.1.0-py3.5.egg/rever/activity.xsh\", line 59, in __call__\n    self.func(*args, **kwargs)\n  File \"/home/scopatz/.local/lib/python3.5/site-packages/rever-0.1.0-py3.5.egg/rever/activities/ghpages.xsh\", line 79, in _func\n    if p.rtn == 0 and q.rtn == 0:\n  File \"/home/scopatz/.local/lib/python3.5/site-packages/xonsh/__amalgam__.py\", line 12839, in rtn\n    return self.returncode\n  File \"/home/scopatz/.local/lib/python3.5/site-packages/xonsh/__amalgam__.py\", line 12826, in returncode\n    self.end()\n  File \"/home/scopatz/.local/lib/python3.5/site-packages/xonsh/__amalgam__.py\", line 12645, in end\n    self._end(tee_output=tee_output)\n  File \"/home/scopatz/.local/lib/python3.5/site-packages/xonsh/__amalgam__.py\", line 12653, in _end\n    for _ in self.tee_stdout():\n  File \"/home/scopatz/.local/lib/python3.5/site-packages/xonsh/__amalgam__.py\", line 12569, in tee_stdout\n    for line in self.iterraw():\n  File \"/home/scopatz/.local/lib/python3.5/site-packages/xonsh/__amalgam__.py\", line 12462, in iterraw\n    self.end(tee_output=False)\n  File \"/home/scopatz/.local/lib/python3.5/site-packages/xonsh/__amalgam__.py\", line 12645, in end\n    self._end(tee_output=tee_output)\n  File \"/home/scopatz/.local/lib/python3.5/site-packages/xonsh/__amalgam__.py\", line 12664, in _end\n    self._raise_subproc_error()\n  File \"/home/scopatz/.local/lib/python3.5/site-packages/xonsh/__amalgam__.py\", line 12774, in _raise_subproc_error\n    output=self.output)\nsubprocess.CalledProcessError: Command '['/usr/bin/git', 'diff', '--exit-code', '--quiet']' returned non-zero exit status 1\nrewinding to a077dbc7a4fec63328bb79b74bf19009923528e7","rev":"ded7c7adfdf7f07ad58d8b04626b9d745aaac092","timestamp":1510795453.5850072}
{"activity":"ghpages","category":"activity-error","message":"activity failed with execption:\nTraceback (most recent call last):\n  File \"/home/scopatz/.local/lib/python3.5/site-packages/rever-0.1.0-py3.5.egg/rever/activity.xsh\", line 59, in __call__\n    self.func(*args, **kwargs)\n  File \"/home/scopatz/.local/lib/python3.5/site-packages/rever-0.1.0-py3.5.egg/rever/activities/ghpages.xsh\", line 79, in _func\n    if p.rtn == 0 and q.rtn == 0:\n  File \"/home/scopatz/.local/lib/python3.5/site-packages/xonsh/__amalgam__.py\", line 12839, in rtn\n    return self.returncode\n  File \"/home/scopatz/.local/lib/python3.5/site-packages/xonsh/__amalgam__.py\", line 12826, in returncode\n    self.end()\n  File \"/home/scopatz/.local/lib/python3.5/site-packages/xonsh/__amalgam__.py\", line 12645, in end\n    self._end(tee_output=tee_output)\n  File \"/home/scopatz/.local/lib/python3.5/site-packages/xonsh/__amalgam__.py\", line 12653, in _end\n    for _ in self.tee_stdout():\n  File \"/home/scopatz/.local/lib/python3.5/site-packages/xonsh/__amalgam__.py\", line 12569, in tee_stdout\n    for line in self.iterraw():\n  File \"/home/scopatz/.local/lib/python3.5/site-packages/xonsh/__amalgam__.py\", line 12462, in iterraw\n    self.end(tee_output=False)\n  File \"/home/scopatz/.local/lib/python3.5/site-packages/xonsh/__amalgam__.py\", line 12645, in end\n    self._end(tee_output=tee_output)\n  File \"/home/scopatz/.local/lib/python3.5/site-packages/xonsh/__amalgam__.py\", line 12664, in _end\n    self._raise_subproc_error()\n  File \"/home/scopatz/.local/lib/python3.5/site-packages/xonsh/__amalgam__.py\", line 12774, in _raise_subproc_error\n    output=self.output)\nsubprocess.CalledProcessError: Command '['/usr/bin/git', 'diff', '--exit-code', '--quiet']' returned non-zero exit status 1\nrewinding to a077dbc7a4fec63328bb79b74bf19009923528e7","rev":"ded7c7adfdf7f07ad58d8b04626b9d745aaac092","timestamp":1510795590.5061736}
{"activity":"ghpages","category":"activity-error","message":"activity failed with execption:\nTraceback (most recent call last):\n  File \"/home/scopatz/.local/lib/python3.5/site-packages/rever-0.1.0-py3.5.egg/rever/activity.xsh\", line 59, in __call__\n    self.func(*args, **kwargs)\n  File \"/home/scopatz/.local/lib/python3.5/site-packages/rever-0.1.0-py3.5.egg/rever/activities/ghpages.xsh\", line 80, in _func\n    'up-to-date.{NO_COLOR}')\n  File \"/home/scopatz/.local/lib/python3.5/site-packages/rever-0.1.0-py3.5.egg/rever/activities/ghpages.xsh\", line 80, in _func\n    'up-to-date.{NO_COLOR}')\n  File \"/home/scopatz/miniconda3/lib/python3.5/bdb.py\", line 48, in trace_dispatch\n    return self.dispatch_line(frame)\n  File \"/home/scopatz/miniconda3/lib/python3.5/bdb.py\", line 67, in dispatch_line\n    if self.quitting: raise BdbQuit\nbdb.BdbQuit\nrewinding to a077dbc7a4fec63328bb79b74bf19009923528e7","rev":"ded7c7adfdf7f07ad58d8b04626b9d745aaac092","timestamp":1510795884.872274}
